I'm sorry, but an uncaught exception occurred.

While running game code:
  File "game/script.rpy", line 10, in script call
    call script_act2_ren
  File "game/scripts/script_act2_ren.rpy", line 87, in script
    MAN """
Exception: Sayer 'MAN' is not defined.

-- Full Traceback ------------------------------------------------------------

Full traceback:
  File "game/script.rpy", line 10, in script call
    call script_act2_ren
  File "game/scripts/script_act2_ren.rpy", line 87, in script
    MAN """
  File "C:\Lab\RenPy\renpy-8.2.1-sdk\renpy\ast.py", line 2557, in execute
    Say.execute(self)
  File "C:\Lab\RenPy\renpy-8.2.1-sdk\renpy\ast.py", line 575, in execute
    who = eval_who(self.who, self.who_fast)
  File "C:\Lab\RenPy\renpy-8.2.1-sdk\renpy\ast.py", line 464, in eval_who
    raise Exception("Sayer '%s' is not defined." % who)
Exception: Sayer 'MAN' is not defined.

Windows-10-10.0.22631 AMD64
Ren'Py 8.2.1.24030407
Project Rizzal 0.2
Mon May 20 10:26:27 2024
